Workbook

Sheet raw data
A1: Projects | B1: Vehicle_ID | C1: Driver_ID | D1: Origin | E1: Destination | F1: Distance_km | G1: Fuel_Consumed_L | H1: Delivery_Status | I1: Delivery_Date
B2: V04 | C2: D01 | D2: Delhi | E2: Pune | F2: 1173 | G2: 108.42 | H2: On-Time | I2: 44953
A3: Sales Performance Dashboard | B3: V06 | C3: D08 | D3: Mumbai | E3: Bangalore | F3: 1727 | G3: 161.33 | H3: On-Time | I3: 44978
A4: Analyzed monthly sales target vs. achievement data and created an interactive dashboard using Power BI. Implemented slicers and KPIs to track category-wise and region-wise performance. | B4: V06 | C4: D08 | D4: Mumbai | E4: Pune | F4: 1459 | G4: 154.7 | H4: On-Time | I4: 44974
A5: Tools Used: Power BI, Excel | B5: V04 | C5: D09 | D5: Hyderabad | E5: Pune | F5: 382 | G5: 26.6 | H5: On-Time | I5: 44975
B6: V06 | C6: D08 | D6: Pune | E6: Mumbai | F6: 398 | G6: 33.2 | H6: On-Time | I6: 44972
A7: Logistics & Fleet Efficiency Analysis | B7: V06 | C7: D07 | D7: Chennai | E7: Mumbai | F7: 1275 | G7: 85.04 | H7: Late | I7: 44982
A8: Built a dashboard to analyze on-time deliveries, fuel efficiency, and cost per km using a logistics dataset. Created DAX measures like fuel efficiency and on-time delivery %. | B8: V07 | C8: D03 | D8: Chennai | E8: Kolkata | F8: 752 | G8: 58.08 | H8: On-Time | I8: 44945
A9: Tools Used: Power BI, DAX, Excel | B9: V02 | C9: D10 | D9: Delhi | E9: Pune | F9: 74 | G9: 5.24 | H9: On-Time | I9: 44927
B10: V02 | C10: D07 | D10: Delhi | E10: Hyderabad | F10: 186 | G10: 16.22 | H10: On-Time | I10: 44980
A11: Bike Buyers Data Analysis | B11: V02 | C11: D02 | D11: Bangalore | E11: Hyderabad | F11: 1375 | G11: 105.21 | H11: Late | I11: 44959
A12: Cleaned and transformed raw dataset, performed demographic-based analysis (age, income, marital status) and visualized purchasing trends using Excel pivot tables and charts. | B12: V06 | C12: D03 | D12: Kolkata | E12: Hyderabad | F12: 419 | G12: 31.17 | H12: On-Time | I12: 44947
A13: Tools Used: Excel, Pivot Tables, Charts | B13: V06 | C13: D01 | D13: Kolkata | E13: Delhi | F13: 751 | G13: 51.77 | H13: On-Time | I13: 44972
A14: T013 | B14: V05 | C14: D04 | D14: Kolkata | E14: Chennai | F14: 1571 | G14: 188.52 | H14: Late | I14: 44959
A15: T014 | B15: V05 | C15: D05 | D15: Hyderabad | E15: Bangalore | F15: 1524 | G15: 104.51 | H15: On-Time | I15: 44973
A16: T015 | B16: V05 | C16: D06 | D16: Kolkata | E16: Mumbai | F16: 1956 | G16: 179.88 | H16: On-Time | I16: 44947
A17: T016 | B17: V05 | C17: D06 | D17: Bangalore | E17: Mumbai | F17: 858 | G17: 92.7 | H17: Late | I17: 44944
A18: T017 | B18: V07 | C18: D07 | D18: Pune | E18: Kolkata | F18: 1269 | G18: 102.91 | H18: On-Time | I18: 44942
A19: T018 | B19: V07 | C19: D10 | D19: Pune | E19: Delhi | F19: 1565 | G19: 107.23 | H19: On-Time | I19: 44969
A20: T019 | B20: V07 | C20: D10 | D20: Hyderabad | E20: Pune | F20: 1796 | G20: 155.52 | H20: On-Time | I20: 44985
A21: T020 | B21: V04 | C21: D02 | D21: Mumbai | E21: Bangalore | F21: 1640 | G21: 148.87 | H21: On-Time | I21: 44932
A22: T021 | B22: V07 | C22: D07 | D22: Delhi | E22: Mumbai | F22: 446 | G22: 31.98 | H22: Late | I22: 44937
... A43: T042 | B43: V05 | C43: D03 | D43: Hyderabad | E43: Chennai | F43: 1245 | G43: 95.14 | H43: On-Time | I43: 44967
A44: T043 | B44: V06 | C44: D06 | D44: Hyderabad | E44: Bangalore | F44: 116+666 | G44: 8.71 | H44: Late | I44: 44932
A45: T044 | B45: V04 | C45: D07 | D45: Delhi | E45: Mumbai | F45: 1259 | G45: 87.59 | H45: Late | I45: 44955
A46: T045 | B46: V02 | C46: D03 | D46: Kolkata | E46: Chennai | F46: 1803 | G46: 211.34 | H46: On-Time | I46: 44970
A47: T046 | B47: V04 | C47: D07 | D47: Chennai | E47: Hyderabad | F47: 1096 | G47: 100.52 | H47: Late | I47: 44947
A48: T047 | B48: V05 | C48: D06 | D48: Hyderabad | E48: Delhi | F48: 572 | G48: 61.6 | H48: On-Time | I48: 44948
A49: T048 | B49: V04 | C49: D01 | D49: Chennai | E49: Bangalore | F49: 1441 | G49: 140.79 | H49: Late | I49: 44985
A50: T049 | B50: V07 | C50: D04 | D50: Bangalore | E50: Mumbai | F50: 1685 | G50: 119.01 | H50: Late | I50: 44973
A51: T050 | B51: V06 | C51: D03 | D51: Mumbai | E51: Delhi | F51: 1233 | G51: 153.35 | H51: On-Time | I51: 44938

Sheet Vehicle_Master
A1: Vehicle_ID | B1: Vehicle_Type | C1: Capacity_kg | D1: Maintenance_Cost
A2: V01 | B2: Van | C2: 8424 | D2: 5633
A3: V02 | B3: Truck | C3: 1970 | D3: 6776
A4: V03 | B4: Truck | C4: 1207 | D4: 18031
A5: V04 | B5: Mini-Truck | C5: 8803 | D5: 9033
A6: V05 | B6: Truck | C6: 9941 | D6: 17751
A7: V06 | B7: Van | C7: 6053 | D7: 5914
A8: V07 | B8: Van | C8: 2598 | D8: 12837
D10: =SUM(D2:D9) -> 75975

Sheet Trip_Data_worksheet
A1: Projects | B1: Vehicle_ID | C1: Driver_ID | D1: Origin | E1: Destination | F1: Route | G1: Distance_km | H1: Fuel_Consumed_L | I1: Fuel Efficiency | J1: Total Fuel Cost(Asuming that Cost Will Be 100 Per Ltr) | K1: Delivery_Status | L1: Vehicle Type | M1: Capacity_kg | N1: Maintenance_Cost | O1: Delivery_Date
A2: T001 | B2: V04 | C2: D01 | D2: Delhi | E2: Pune | F2: =_xlfn.CONCAT(Trip_Data_worksheet!$D2," - ",Trip_Data_worksheet!$E2) -> Delhi - Pune | G2: 1173 | H2: 108.42 | I2: =Trip_Data_worksheet!$G2/Trip_Data_worksheet!$H2 -> 10.819037 | J2: =Trip_Data_worksheet!$H2*100 -> 10842 | K2: On-Time | L2: {=_xlfn.XLOOKUP(Trip_Data_worksheet!$B2,Table2[[#All],[Vehicle_ID]],Table2[[#All],[Vehicle_Type]],0)} -> Mini-Truck | M2: {=_xlfn.XLOOKUP(Trip_Data_worksheet!$B2,Table2[[#All],[Vehicle_ID]],Table2[[#All],[Capacity_kg]],0)} -> 8803 | N2: {=_xlfn.XLOOKUP(Trip_Data_worksheet!$B2,Table2[[#All],[Vehicle_ID]],Table2[[#All],[Maintenance_Cost]],0)} -> 9033 | O2: 44953
A3: T002 | B3: V06 | C3: D08 | D3: Mumbai | E3: Bangalore | F3: =_xlfn.CONCAT(Trip_Data_worksheet!$D3," - ",Trip_Data_worksheet!$E3) -> Mumbai - Bangalore | G3: 1727 | H3: 161.33 | I3: =Trip_Data_worksheet!$G3/Trip_Data_worksheet!$H3 -> 10.704767 | J3: =Trip_Data_worksheet!$H3*100 -> 16133 | K3: On-Time | L3: {=_xlfn.XLOOKUP(Trip_Data_worksheet!$B3,Table2[[#All],[Vehicle_ID]],Table2[[#All],[Vehicle_Type]],0)} -> Van | M3: {=_xlfn.XLOOKUP(Trip_Data_worksheet!$B3,Table2[[#All],[Vehicle_ID]],Table2[[#All],[Capacity_kg]],0)} -> 6053 | N3: {=_xlfn.XLOOKUP(Trip_Data_worksheet!$B3,Table2[[#All],[Vehicle_ID]],Table2[[#All],[Maintenance_Cost]],0)} -> 5914 | O3: 44978
A4: T003 | B4: V06 | C4: D08 | D4: Mumbai | E4: Pune | F4: =_xlfn.CONCAT(Trip_Data_worksheet!$D4," - ",Trip_Data_worksheet!$E4) -> Mumbai - Pune | G4: 1459 | H4: 154.7 | I4: =Trip_Data_worksheet!$G4/Trip_Data_worksheet!$H4 -> 9.4311571 | J4: =Trip_Data_worksheet!$H4*100 -> 15470 | K4: On-Time | L4: {=_xlfn.XLOOKUP(Trip_Data_worksheet!$B4,Table2[[#All],[Vehicle_ID]],Table2[[#All],[Vehicle_Type]],0)} -> Van | M4: {=_xlfn.XLOOKUP(Trip_Data_worksheet!$B4,Table2[[#All],[Vehicle_ID]],Table2[[#All],[Capacity_kg]],0)} -> 6053 | N4: {=_xlfn.XLOOKUP(Trip_Data_worksheet!$B4,Table2[[#All],[Vehicle_ID]],Table2[[#All],[Maintenance_Cost]],0)} -> 5914 | O4: 44974
A5: T004 | B5: V04 | C5: D09 | D5: Hyderabad | E5: Pune | F5: =_xlfn.CONCAT(Trip_Data_worksheet!$D5," - ",Trip_Data_worksheet!$E5) -> Hyderabad - Pune | G5: 382 | H5: 26.6 | I5: =Trip_Data_worksheet!$G5/Trip_Data_worksheet!$H5 -> 14.360902 | J5: =Trip_Data_worksheet!$H5*100 -> 2660 | K5: On-Time | L5: {=_xlfn.XLOOKUP(Trip_Data_worksheet!$B5,Table2[[#All],[Vehicle_ID]],Table2[[#All],[Vehicle_Type]],0)} -> Mini-Truck | M5: {=_xlfn.XLOOKUP(Trip_Data_worksheet!$B5,Table2[[#All],[Vehicle_ID]],Table2[[#All],[Capacity_kg]],0)} -> 8803 | N5: {=_xlfn.XLOOKUP(Trip_Data_worksheet!$B5,Table2[[#All],[Vehicle_ID]],Table2[[#All],[Maintenance_Cost]],0)} -> 9033 | O5: 44975
A6: T005 | B6: V06 | C6: D08 | D6: Pune | E6: Mumbai | F6: =_xlfn.CONCAT(Trip_Data_worksheet!$D6," - ",Trip_Data_worksheet!$E6) -> Pune - Mumbai | G6: 398 | H6: 33.2 | I6: =Trip_Data_worksheet!$G6/Trip_Data_worksheet!$H6 -> 11.987952 | J6: =Trip_Data_worksheet!$H6*100 -> 3320 | K6: On-Time | L6: {=_xlfn.XLOOKUP(Trip_Data_worksheet!$B6,Table2[[#All],[Vehicle_ID]],Table2[[#All],[Vehicle_Type]],0)} -> Van | M6: {=_xlfn.XLOOKUP(Trip_Data_worksheet!$B6,Table2[[#All],[Vehicle_ID]],Table2[[#All],[Capacity_kg]],0)} -> 6053 | N6: {=_xlfn.XLOOKUP(Trip_Data_worksheet!$B6,Table2[[#All],[Vehicle_ID]],Table2[[#All],[Maintenance_Cost]],0)} -> 5914 | O6: 44972
A7: T006 | B7: V06 | C7: D07 | D7: Chennai | E7: Mumbai | F7: =_xlfn.CONCAT(Trip_Data_worksheet!$D7," - ",Trip_Data_worksheet!$E7) -> Chennai - Mumbai | G7: 1275 | H7: 85.04 | I7: =Trip_Data_worksheet!$G7/Trip_Data_worksheet!$H7 -> 14.992944 | J7: =Trip_Data_worksheet!$H7*100 -> 8504 | K7: Late | L7: {=_xlfn.XLOOKUP(Trip_Data_worksheet!$B7,Table2[[#All],[Vehicle_ID]],Table2[[#All],[Vehicle_Type]],0)} -> Van | M7: {=_xlfn.XLOOKUP(Trip_Data_worksheet!$B7,Table2[[#All],[Vehicle_ID]],Table2[[#All],[Capacity_kg]],0)} -> 6053 | N7: {=_xlfn.XLOOKUP(Trip_Data_worksheet!$B7,Table2[[#All],[Vehicle_ID]],Table2[[#All],[Maintenance_Cost]],0)} -> 5914 | O7: 44982
A8: T007 | B8: V07 | C8: D03 | D8: Chennai | E8: Kolkata | F8: =_xlfn.CONCAT(Trip_Data_worksheet!$D8," - ",Trip_Data_worksheet!$E8) -> Chennai - Kolkata | G8: 752 | H8: 58.08 | I8: =Trip_Data_worksheet!$G8/Trip_Data_worksheet!$H8 -> 12.947658 | J8: =Trip_Data_worksheet!$H8*100 -> 5808 | K8: On-Time | L8: {=_xlfn.XLOOKUP(Trip_Data_worksheet!$B8,Table2[[#All],[Vehicle_ID]],Table2[[#All],[Vehicle_Type]],0)} -> Van | M8: {=_xlfn.XLOOKUP(Trip_Data_worksheet!$B8,Table2[[#All],[Vehicle_ID]],Table2[[#All],[Capacity_kg]],0)} -> 2598 | N8: {=_xlfn.XLOOKUP(Trip_Data_worksheet!$B8,Table2[[#All],[Vehicle_ID]],Table2[[#All],[Maintenance_Cost]],0)} -> 12837 | O8: 44945
A9: T008 | B9: V02 | C9: D10 | D9: Delhi | E9: Pune | F9: =_xlfn.CONCAT(Trip_Data_worksheet!$D9," - ",Trip_Data_worksheet!$E9) -> Delhi - Pune | G9: 74 | H9: 5.24 | I9: =Trip_Data_worksheet!$G9/Trip_Data_worksheet!$H9 -> 14.122137 | J9: =Trip_Data_worksheet!$H9*100 -> 524 | K9: On-Time | L9: {=_xlfn.XLOOKUP(Trip_Data_worksheet!$B9,Table2[[#All],[Vehicle_ID]],Table2[[#All],[Vehicle_Type]],0)} -> Truck | M9: {=_xlfn.XLOOKUP(Trip_Data_worksheet!$B9,Table2[[#All],[Vehicle_ID]],Table2[[#All],[Capacity_kg]],0)} -> 1970 | N9: {=_xlfn.XLOOKUP(Trip_Data_worksheet!$B9,Table2[[#All],[Vehicle_ID]],Table2[[#All],[Maintenance_Cost]],0)} -> 6776 | O9: 44927
A10: T009 | B10: V02 | C10: D07 | D10: Delhi | E10: Hyderabad | F10: =_xlfn.CONCAT(Trip_Data_worksheet!$D10," - ",Trip_Data_worksheet!$E10) -> Delhi - Hyderabad | G10: 186 | H10: 16.22 | I10: =Trip_Data_worksheet!$G10/Trip_Data_worksheet!$H10 -> 11.467324 | J10: =Trip_Data_worksheet!$H10*100 -> 1622 | K10: On-Time | L10: {=_xlfn.XLOOKUP(Trip_Data_worksheet!$B10,Table2[[#All],[Vehicle_ID]],Table2[[#All],[Vehicle_Type]],0)} -> Truck | M10: {=_xlfn.XLOOKUP(Trip_Data_worksheet!$B10,Table2[[#All],[Vehicle_ID]],Table2[[#All],[Capacity_kg]],0)} -> 1970 | N10: {=_xlfn.XLOOKUP(Trip_Data_worksheet!$B10,Table2[[#All],[Vehicle_ID]],Table2[[#All],[Maintenance_Cost]],0)} -> 6776 | O10: 44980
A11: T010 | B11: V02 | C11: D02 | D11: Bangalore | E11: Hyderabad | F11: =_xlfn.CONCAT(Trip_Data_worksheet!$D11," - ",Trip_Data_worksheet!$E11) -> Bangalore - Hyderabad | G11: 1375 | H11: 105.21 | I11: =Trip_Data_worksheet!$G11/Trip_Data_worksheet!$H11 -> 13.0691 | J11: =Trip_Data_worksheet!$H11*100 -> 10521 | K11: Late | L11: {=_xlfn.XLOOKUP(Trip_Data_worksheet!$B11,Table2[[#All],[Vehicle_ID]],Table2[[#All],[Vehicle_Type]],0)} -> Truck | M11: {=_xlfn.XLOOKUP(Trip_Data_worksheet!$B11,Table2[[#All],[Vehicle_ID]],Table2[[#All],[Capacity_kg]],0)} -> 1970 | N11: {=_xlfn.XLOOKUP(Trip_Data_worksheet!$B11,Table2[[#All],[Vehicle_ID]],Table2[[#All],[Maintenance_Cost]],0)} -> 6776 | O11: 44959
A12: T011 | B12: V06 | C12: D03 | D12: Kolkata | E12: Hyderabad | F12: =_xlfn.CONCAT(Trip_Data_worksheet!$D12," - ",Trip_Data_worksheet!$E12) -> Kolkata - Hyderabad | G12: 419 | H12: 31.17 | I12: =Trip_Data_worksheet!$G12/Trip_Data_worksheet!$H12 -> 13.442413 | J12: =Trip_Data_worksheet!$H12*100 -> 3117 | K12: On-Time | L12: {=_xlfn.XLOOKUP(Trip_Data_worksheet!$B12,Table2[[#All],[Vehicle_ID]],Table2[[#All],[Vehicle_Type]],0)} -> Van | M12: {=_xlfn.XLOOKUP(Trip_Data_worksheet!$B12,Table2[[#All],[Vehicle_ID]],Table2[[#All],[Capacity_kg]],0)} -> 6053 | N12: {=_xlfn.XLOOKUP(Trip_Data_worksheet!$B12,Table2[[#All],[Vehicle_ID]],Table2[[#All],[Maintenance_Cost]],0)} -> 5914 | O12: 44947
A13: T012 | B13: V06 | C13: D01 | D13: Kolkata | E13: Delhi | F13: =_xlfn.CONCAT(Trip_Data_worksheet!$D13," - ",Trip_Data_worksheet!$E13) -> Kolkata - Delhi | G13: 751 | H13: 51.77 | I13: =Trip_Data_worksheet!$G13/Trip_Data_worksheet!$H13 -> 14.506471 | J13: =Trip_Data_worksheet!$H13*100 -> 5177 | K13: On-Time | L13: {=_xlfn.XLOOKUP(Trip_Data_worksheet!$B13,Table2[[#All],[Vehicle_ID]],Table2[[#All],[Vehicle_Type]],0)} -> Van | M13: {=_xlfn.XLOOKUP(Trip_Data_worksheet!$B13,Table2[[#All],[Vehicle_ID]],Table2[[#All],[Capacity_kg]],0)} -> 6053 | N13: {=_xlfn.XLOOKUP(Trip_Data_worksheet!$B13,Table2[[#All],[Vehicle_ID]],Table2[[#All],[Maintenance_Cost]],0)} -> 5914 | O13: 44972
... A43: T042 | B43: V05 | C43: D03 | D43: Hyderabad | E43: Chennai | F43: =_xlfn.CONCAT(Trip_Data_worksheet!$D43," - ",Trip_Data_worksheet!$E43) -> Hyderabad - Chennai | G43: 1245 | H43: 95.14 | I43: =Trip_Data_worksheet!$G43/Trip_Data_worksheet!$H43 -> 13.085979 | J43: =Trip_Data_worksheet!$H43*100 -> 9514 | K43: On-Time | L43: {=_xlfn.XLOOKUP(Trip_Data_worksheet!$B43,Table2[[#All],[Vehicle_ID]],Table2[[#All],[Vehicle_Type]],0)} -> Truck | M43: {=_xlfn.XLOOKUP(Trip_Data_worksheet!$B43,Table2[[#All],[Vehicle_ID]],Table2[[#All],[Capacity_kg]],0)} -> 9941 | N43: {=_xlfn.XLOOKUP(Trip_Data_worksheet!$B43,Table2[[#All],[Vehicle_ID]],Table2[[#All],[Maintenance_Cost]],0)} -> 17751 | O43: 44967
A44: T043 | B44: V06 | C44: D06 | D44: Hyderabad | E44: Bangalore | F44: =_xlfn.CONCAT(Trip_Data_worksheet!$D44," - ",Trip_Data_worksheet!$E44) -> Hyderabad - Bangalore | G44: =116+666 -> 782 | H44: 8.71 | I44: =Trip_Data_worksheet!$G44/Trip_Data_worksheet!$H44 -> 89.78186 | J44: =Trip_Data_worksheet!$H44*100 -> 871 | K44: Late | L44: {=_xlfn.XLOOKUP(Trip_Data_worksheet!$B44,Table2[[#All],[Vehicle_ID]],Table2[[#All],[Vehicle_Type]],0)} -> Van | M44: {=_xlfn.XLOOKUP(Trip_Data_worksheet!$B44,Table2[[#All],[Vehicle_ID]],Table2[[#All],[Capacity_kg]],0)} -> 6053 | N44: {=_xlfn.XLOOKUP(Trip_Data_worksheet!$B44,Table2[[#All],[Vehicle_ID]],Table2[[#All],[Maintenance_Cost]],0)} -> 5914 | O44: 44932
A45: T044 | B45: V04 | C45: D07 | D45: Delhi | E45: Mumbai | F45: =_xlfn.CONCAT(Trip_Data_worksheet!$D45," - ",Trip_Data_worksheet!$E45) -> Delhi - Mumbai | G45: 1259 | H45: 87.59 | I45: =Trip_Data_worksheet!$G45/Trip_Data_worksheet!$H45 -> 14.373787 | J45: =Trip_Data_worksheet!$H45*100 -> 8759 | K45: Late | L45: {=_xlfn.XLOOKUP(Trip_Data_worksheet!$B45,Table2[[#All],[Vehicle_ID]],Table2[[#All],[Vehicle_Type]],0)} -> Mini-Truck | M45: {=_xlfn.XLOOKUP(Trip_Data_worksheet!$B45,Table2[[#All],[Vehicle_ID]],Table2[[#All],[Capacity_kg]],0)} -> 8803 | N45: {=_xlfn.XLOOKUP(Trip_Data_worksheet!$B45,Table2[[#All],[Vehicle_ID]],Table2[[#All],[Maintenance_Cost]],0)} -> 9033 | O45: 44955
A46: T045 | B46: V02 | C46: D03 | D46: Kolkata | E46: Chennai | F46: =_xlfn.CONCAT(Trip_Data_worksheet!$D46," - ",Trip_Data_worksheet!$E46) -> Kolkata - Chennai | G46: 1803 | H46: 211.34 | I46: =Trip_Data_worksheet!$G46/Trip_Data_worksheet!$H46 -> 8.5312766 | J46: =Trip_Data_worksheet!$H46*100 -> 21134 | K46: On-Time | L46: {=_xlfn.XLOOKUP(Trip_Data_worksheet!$B46,Table2[[#All],[Vehicle_ID]],Table2[[#All],[Vehicle_Type]],0)} -> Truck | M46: {=_xlfn.XLOOKUP(Trip_Data_worksheet!$B46,Table2[[#All],[Vehicle_ID]],Table2[[#All],[Capacity_kg]],0)} -> 1970 | N46: {=_xlfn.XLOOKUP(Trip_Data_worksheet!$B46,Table2[[#All],[Vehicle_ID]],Table2[[#All],[Maintenance_Cost]],0)} -> 6776 | O46: 44970
A47: T046 | B47: V04 | C47: D07 | D47: Chennai | E47: Hyderabad | F47: =_xlfn.CONCAT(Trip_Data_worksheet!$D47," - ",Trip_Data_worksheet!$E47) -> Chennai - Hyderabad | G47: 1096 | H47: 100.52 | I47: =Trip_Data_worksheet!$G47/Trip_Data_worksheet!$H47 -> 10.903303 | J47: =Trip_Data_worksheet!$H47*100 -> 10052 | K47: Late | L47: {=_xlfn.XLOOKUP(Trip_Data_worksheet!$B47,Table2[[#All],[Vehicle_ID]],Table2[[#All],[Vehicle_Type]],0)} -> Mini-Truck | M47: {=_xlfn.XLOOKUP(Trip_Data_worksheet!$B47,Table2[[#All],[Vehicle_ID]],Table2[[#All],[Capacity_kg]],0)} -> 8803 | N47: {=_xlfn.XLOOKUP(Trip_Data_worksheet!$B47,Table2[[#All],[Vehicle_ID]],Table2[[#All],[Maintenance_Cost]],0)} -> 9033 | O47: 44947
A48: T047 | B48: V05 | C48: D06 | D48: Hyderabad | E48: Delhi | F48: =_xlfn.CONCAT(Trip_Data_worksheet!$D48," - ",Trip_Data_worksheet!$E48) -> Hyderabad - Delhi | G48: 572 | H48: 61.6 | I48: =Trip_Data_worksheet!$G48/Trip_Data_worksheet!$H48 -> 9.2857143 | J48: =Trip_Data_worksheet!$H48*100 -> 6160 | K48: On-Time | L48: {=_xlfn.XLOOKUP(Trip_Data_worksheet!$B48,Table2[[#All],[Vehicle_ID]],Table2[[#All],[Vehicle_Type]],0)} -> Truck | M48: {=_xlfn.XLOOKUP(Trip_Data_worksheet!$B48,Table2[[#All],[Vehicle_ID]],Table2[[#All],[Capacity_kg]],0)} -> 9941 | N48: {=_xlfn.XLOOKUP(Trip_Data_worksheet!$B48,Table2[[#All],[Vehicle_ID]],Table2[[#All],[Maintenance_Cost]],0)} -> 17751 | O48: 44948
A49: T048 | B49: V04 | C49: D01 | D49: Chennai | E49: Bangalore | F49: =_xlfn.CONCAT(Trip_Data_worksheet!$D49," - ",Trip_Data_worksheet!$E49) -> Chennai - Bangalore | G49: 1441 | H49: 140.79 | I49: =Trip_Data_worksheet!$G49/Trip_Data_worksheet!$H49 -> 10.235102 | J49: =Trip_Data_worksheet!$H49*100 -> 14079 | K49: Late | L49: {=_xlfn.XLOOKUP(Trip_Data_worksheet!$B49,Table2[[#All],[Vehicle_ID]],Table2[[#All],[Vehicle_Type]],0)} -> Mini-Truck | M49: {=_xlfn.XLOOKUP(Trip_Data_worksheet!$B49,Table2[[#All],[Vehicle_ID]],Table2[[#All],[Capacity_kg]],0)} -> 8803 | N49: {=_xlfn.XLOOKUP(Trip_Data_worksheet!$B49,Table2[[#All],[Vehicle_ID]],Table2[[#All],[Maintenance_Cost]],0)} -> 9033 | O49: 44985
A50: T049 | B50: V07 | C50: D04 | D50: Bangalore | E50: Mumbai | F50: =_xlfn.CONCAT(Trip_Data_worksheet!$D50," - ",Trip_Data_worksheet!$E50) -> Bangalore - Mumbai | G50: 1685 | H50: 119.01 | I50: =Trip_Data_worksheet!$G50/Trip_Data_worksheet!$H50 -> 14.158474 | J50: =Trip_Data_worksheet!$H50*100 -> 11901 | K50: Late | L50: {=_xlfn.XLOOKUP(Trip_Data_worksheet!$B50,Table2[[#All],[Vehicle_ID]],Table2[[#All],[Vehicle_Type]],0)} -> Van | M50: {=_xlfn.XLOOKUP(Trip_Data_worksheet!$B50,Table2[[#All],[Vehicle_ID]],Table2[[#All],[Capacity_kg]],0)} -> 2598 | N50: {=_xlfn.XLOOKUP(Trip_Data_worksheet!$B50,Table2[[#All],[Vehicle_ID]],Table2[[#All],[Maintenance_Cost]],0)} -> 12837 | O50: 44973
A51: T050 | B51: V06 | C51: D03 | D51: Mumbai | E51: Delhi | F51: =_xlfn.CONCAT(Trip_Data_worksheet!$D51," - ",Trip_Data_worksheet!$E51) -> Mumbai - Delhi | G51: 1233 | H51: 153.35 | I51: =Trip_Data_worksheet!$G51/Trip_Data_worksheet!$H51 -> 8.0404304 | J51: =Trip_Data_worksheet!$H51*100 -> 15335 | K51: On-Time | L51: {=_xlfn.XLOOKUP(Trip_Data_worksheet!$B51,Table2[[#All],[Vehicle_ID]],Table2[[#All],[Vehicle_Type]],0)} -> Van | M51: {=_xlfn.XLOOKUP(Trip_Data_worksheet!$B51,Table2[[#All],[Vehicle_ID]],Table2[[#All],[Capacity_kg]],0)} -> 6053 | N51: {=_xlfn.XLOOKUP(Trip_Data_worksheet!$B51,Table2[[#All],[Vehicle_ID]],Table2[[#All],[Maintenance_Cost]],0)} -> 5914 | O51: 44938
A54: Logistics data analysis
A56: Total number of trips | G56: =COUNTA(_xlfn.UNIQUE(Trip_Data_worksheet!$A$2:$A$51)) -> 50
A57: Total Distance covered | G57: =SUM(G2:G56) -> 53657 | L57: =COUNTIFS(Trip_Data_worksheet!$B$2:$B$51,"V01",Trip_Data_worksheet!$K$2:$K$51,"On-Time") -> 1
A58: Total fuel consumed | G58: =SUM(Trip_Data_worksheet!$H$2:$H$51) -> 4629.8
A59: Assuming fuel cost as Rs.100/- ,Total fuel cost of the company | G59: =SUM(Trip_Data_worksheet!$J$2:$J$51) -> 462980
A61: Total number of On-Time trips | G61: =COUNTIF(Trip_Data_worksheet!$K$2:$K$51,K2) -> 30
A62: Total number of Late trips | G62: =COUNTIF(Trip_Data_worksheet!$K$2:$K$51,K7) -> 20
A63: On-Time delivery % of company | G63: =G61/G56 -> 0.6
A64: Total number of distinct routes | G64: =COUNTA(_xlfn.UNIQUE(Trip_Data_worksheet!$F$2:$F$51)) -> 31
A65: Total maintance cost of the 7 vehicles | G65: =SUM(Table2[Maintenance_Cost]) -> 75975
A66: Total number of drivers | G66: =COUNTA(_xlfn.UNIQUE(Trip_Data_worksheet!$C$2:$C$51)) -> 10
A67: Total fuel efficiency | G67: =G57/G58 -> 11.589486
A70: DRIVERS | C70: No of On-Time trips | D70: No.of total trips | E70: % of on time trips
A72: D01 | C72: =COUNTIFS(Table1[Driver_ID],C2,Table1[Delivery_Status],K2) -> 4 | D72: =COUNTIF(Table1[Driver_ID],A72) -> 6 | E72: =C72/D72 -> 0.66666667
A73: D02 | C73: =COUNTIFS(C2:C51,C11,K2:K51,K2) -> 1 | D73: =COUNTIF(Table1[Driver_ID],A73) -> 3 | E73: =C73/D73 -> 0.33333333
A74: D03 | C74: =COUNTIFS(C2:C51,C12,K2:K51,K2) -> 6 | D74: =COUNTIF(Table1[Driver_ID],A74) -> 6 | E74: =C74/D74 -> 1
A75: D04 | C75: =COUNTIFS(C2:C51,C14,K2:K51,K2) -> 3 | D75: =COUNTIF(Table1[Driver_ID],A75) -> 6 | E75: =C75/D75 -> 0.5
A76: D05 | C76: =COUNTIFS(C2:C51,C15,K2:K51,K2) -> 1 | D76: =COUNTIF(Table1[Driver_ID],A76) -> 1 | E76: =C76/D76 -> 1
...

Sheet pivot analysis
A1: Delivery_Status | B1: On-Time
A3: Row Labels | B3: Count of Delivery_Status
A4: D01 | B4: 4
A5: D02 | B5: 1
A6: D03 | B6: 6
A7: D04 | B7: 3
A8: D05 | B8: 1
A9: D06 | B9: 3
A10: D07 | B10: 2
A11: D08 | B11: 3
A12: D09 | B12: 3
A13: D10 | B13: 4
A14: Grand Total | B14: 30
A22: Row Labels | B22: Sum of Fuel_Consumed_L
A23: Bangalore - Chennai | B23: 120.65
A24: Bangalore - Hyderabad | B24: 105.21
A25: Bangalore - Mumbai | B25: 363.07
A26: Bangalore - Pune | B26: 37.39
A27: Chennai - Bangalore | B27: 140.79
A28: Chennai - Delhi | B28: 197.55
A29: Chennai - Hyderabad | B29: 100.52
A30: Chennai - Kolkata | B30: 58.08
A31: Chennai - Mumbai | B31: 85.04
A32: Chennai - Pune | B32: 131.01
A33: Delhi - Bangalore | B33: 70.4
A34: Delhi - Hyderabad | B34: 110.46
... A54: Grand Total | B54: 4629.8
A59: Row Labels | B59: Sum of Fuel Efficiency
A60: V01 | B60: 32.799054
A61: V02 | B61: 78.132901
A62: V03 | B62: 24.11944
A63: V04 | B63: 115.09408
A64: V05 | B64: 116.82542
A65: V06 | B65: 216.09173
A66: V07 | B66: 91.764424
A67: Grand Total | B67: 674.82706
A73: Row Labels | B73: Sum of Maintenance_Cost
A74: V01 | B74: 16899
A75: V02 | B75: 47432
A76: V03 | B76: 36062
...

Sheet workdone 
A1: Works done in excel for the project
A3: 1 | B3: Both sheets combined together for easy and accurate analysis
A4: 2 | B4: checked for dupicate values(Nill),data inconsistancy,Missing values
A5: 3 | B5: Distance format in F44 is corrected and converted it to numbers
A6: 4 | B6: All Data types are corrected to the right format
A7: 5 | B7: Abnormalities in the trip ID colum is corrected and changed it to T001-T012
A8: 6 | B8: New route column is defined to compare the fuel effieciency and performance in each routes
A9: 7 | B9: fuel efficiency ,Total fuel cost are calculated
A10: 8 | B10: Important measures like total ontime trips,no of late trips,total cost of fuel ,fuel efficiecy are calculated to analyse the fleet performance and derive an insight
